# 错误处理

前面已经展示了一些例子，用于说明在一部编程中 Promise 拒绝（调用reject(..)有意拒绝或JavaScript 异常导致得无意拒绝）如何使得错误处理更完善。我们来回顾一下，并明确解释一下前面没有说明得几个细节。

对多数开发者来说，错误处理最自然的形式就是同步得 try..catch 结构。遗憾得是，它只能是同步得，无法用于异步代码模式:
```
function foo(){
  setTimeout(function(){
    baz.bar()
  }, 100)
}

try{
  foo()
  // 后面从 `baz.bar()` 抛出全局错误
}
catch(err){
  // 永远不会到达这里
}
```
try..catch 当然很好，但是无法跨异步操作工作。也就是说，还需要一些额外的环境支持，我们会在第 4 章关于生成器的部分介绍这些环境支持。

在回调中，一些模式化的错误处理方式已经出现，最值得一提的是 error-first 回调 风格：
```
function foo(cb){
  setTimeout(function(){
    try {
      var x = baz.bar();
      cb(null, x); // 成功！
    }
    catch(err) {
      cb(err)
    }
  }, 100)
}

foo(function(err, val){
  if(err){
    console.error(err);
  }
  else {
    console.log(val)
  }
})
```

>只有在 baz.bar() 调用会同步地立即成功或失败的情况下，这里的 try..catch 才能工作。如果 baz.bar() 本身有自己的异步完成函数，其中的任何异步错误都将无法捕捉到。

传给 foo(..) 的回调函数保留第一个参数 err ，用于在出错时接收到信号。如果其存在的话，就认为出错；否则就认为是成功。

严格说来，这一类错误处理是支持异步的，但完全无法很好地组合。多级 error-first 回调交织在一起，再加上这些无所不在的 if 检查语句，
都不可避免地导致了回调地狱的风险（参见第 2 章）。

我们回到 Promise 中的错误处理，其中拒绝处理函数被传递给 then(..) 。Promise 没有采用流行的error-first 回调设计风格，
而是使用了分离回调（split-callback）风格。一个回调用于完成情况，一个回调用于拒绝情况：
```
var p = Promise.reject('Oops');

p.then(
  function fulfilled(){
    // 永远不会到达这里
  },
  function reject(err) {
    console.log(err) // "Oops"
  }
)
```
尽管表面看来，这种出错处理模式很合理，但彻底掌握 Promise 错误处理的各种细微差别常常还是有些难度的。

考虑:
```
var p = Promise.resolve(42);

p.then(
  function fulfilled(msg){
    //  数字没有 string 函数，所以会抛出错误
    console.log(msg.toLowerCase())
  },
  function rejected(err) {
    // 永远不会到达这里
  }
)
```
如果 msg.toLowerCase() 合法地抛出一个错误（事实确实如此！），为什么我们的错误处理函数没有得到通知呢？正如前面解释过的，这是因为那个错误处理函数是为 promise p 准备的，而这个promise 已经用值 42 填充了。promise p 是不可变的，所以唯一可以被通知这个错误的 promise 是从 p.then(..) 返回的那一个，但我们在此例中没有捕捉。

这应该清晰地解释了为什么 Promise 的错误处理易于出错。这非常容易造成错误被吞掉，而这极少是出于你的本意。

>如果通过无效的方式使用 Promise API，并且出现一个错误阻碍了正常的Promise 构造，那么结果会得到一个立即抛出的异常，而不是一个被拒绝的 Promise。这里是一些错误使用导致 Promise 构造失败的例 子：new Promise(null) 、、Promise.all()、Promise.race(42) ，等等。如果一开始你就没能有效使用 Promise API 真正构造出一个Promise，那就无法得到一个被拒绝的 Promise ！